{"name": "Verify that Sign-In with existing account works", "status": "broken", "statusDetails": {"message": "requests.exceptions.ConnectionError: HTTPSConnectionPool(host='www.homedepot.com', port=443): Max retries exceeded with url: /customer/auth/v1/signin (Caused by NewConnectionError('<urllib3.connection.VerifiedHTTPSConnection object at 0x030A1EB0>: Failed to establish a new connection: [WinError 10060] A connection attempt failed because the connected party did not properly respond after a period of time, or established connection failed because connected host has failed to respond'))\n", "trace": "  File \"c:\\users\\oleg3\\pycharmprojects\\homedepot\\venv\\lib\\site-packages\\behave\\model.py\", line 1329, in run\n    match.run(runner.context)\n  File \"c:\\users\\oleg3\\pycharmprojects\\homedepot\\venv\\lib\\site-packages\\behave\\matchers.py\", line 98, in run\n    self.func(context, *args, **kwargs)\n  File \"features\\steps\\main_page_steps.py\", line 93, in verify_log_in\n    context.app.sign_in_page.verify_log_in(url)\n  File \"C:\\Users\\oleg3\\PycharmProjects\\homedepot\\pages\\sign_in_page.py\", line 63, in verify_log_in\n    self.verify_login(url)\n  File \"C:\\Users\\oleg3\\PycharmProjects\\homedepot\\pages\\base_page.py\", line 100, in verify_login\n    x = requests.get(url)\n  File \"c:\\users\\oleg3\\pycharmprojects\\homedepot\\venv\\lib\\site-packages\\requests\\api.py\", line 76, in get\n    return request('get', url, params=params, **kwargs)\n  File \"c:\\users\\oleg3\\pycharmprojects\\homedepot\\venv\\lib\\site-packages\\requests\\api.py\", line 61, in request\n    return session.request(method=method, url=url, **kwargs)\n  File \"c:\\users\\oleg3\\pycharmprojects\\homedepot\\venv\\lib\\site-packages\\requests\\sessions.py\", line 530, in request\n    resp = self.send(prep, **send_kwargs)\n  File \"c:\\users\\oleg3\\pycharmprojects\\homedepot\\venv\\lib\\site-packages\\requests\\sessions.py\", line 643, in send\n    r = adapter.send(request, **kwargs)\n  File \"c:\\users\\oleg3\\pycharmprojects\\homedepot\\venv\\lib\\site-packages\\requests\\adapters.py\", line 516, in send\n    raise ConnectionError(e, request=request)\n"}, "steps": [{"name": "Given Open Homedepot page", "status": "passed", "start": 1586308577214, "stop": 1586308581093}, {"name": "When Click account button", "status": "passed", "start": 1586308581093, "stop": 1586308582401}, {"name": "And Check button Sign out", "status": "passed", "start": 1586308582402, "stop": 1586308582445}, {"name": "And Click 'register' button", "status": "passed", "start": 1586308582445, "stop": 1586308589015}, {"name": "And Fill email field with oleg31950@gmail.com", "status": "passed", "start": 1586308589015, "stop": 1586308589345}, {"name": "And Fill password field with 12345th78", "status": "passed", "start": 1586308589346, "stop": 1586308589548}, {"name": "And Fill zip code field with 98661", "status": "passed", "start": 1586308589548, "stop": 1586308589786}, {"name": "And Fill Phone field with 5038050714", "status": "passed", "start": 1586308589786, "stop": 1586308591494}, {"name": "And Verify my mobile number, click", "status": "passed", "start": 1586308591494, "stop": 1586308591773}, {"name": "And Click submit", "status": "passed", "start": 1586308591773, "stop": 1586308592009}, {"name": "Then Expected login will be complete successfully https://www.homedepot.com/customer/auth/v1/signin", "status": "broken", "statusDetails": {"message": "requests.exceptions.ConnectionError: HTTPSConnectionPool(host='www.homedepot.com', port=443): Max retries exceeded with url: /customer/auth/v1/signin (Caused by NewConnectionError('<urllib3.connection.VerifiedHTTPSConnection object at 0x030A1EB0>: Failed to establish a new connection: [WinError 10060] A connection attempt failed because the connected party did not properly respond after a period of time, or established connection failed because connected host has failed to respond'))\n", "trace": "  File \"c:\\users\\oleg3\\pycharmprojects\\homedepot\\venv\\lib\\site-packages\\behave\\model.py\", line 1329, in run\n    match.run(runner.context)\n  File \"c:\\users\\oleg3\\pycharmprojects\\homedepot\\venv\\lib\\site-packages\\behave\\matchers.py\", line 98, in run\n    self.func(context, *args, **kwargs)\n  File \"features\\steps\\main_page_steps.py\", line 93, in verify_log_in\n    context.app.sign_in_page.verify_log_in(url)\n  File \"C:\\Users\\oleg3\\PycharmProjects\\homedepot\\pages\\sign_in_page.py\", line 63, in verify_log_in\n    self.verify_login(url)\n  File \"C:\\Users\\oleg3\\PycharmProjects\\homedepot\\pages\\base_page.py\", line 100, in verify_login\n    x = requests.get(url)\n  File \"c:\\users\\oleg3\\pycharmprojects\\homedepot\\venv\\lib\\site-packages\\requests\\api.py\", line 76, in get\n    return request('get', url, params=params, **kwargs)\n  File \"c:\\users\\oleg3\\pycharmprojects\\homedepot\\venv\\lib\\site-packages\\requests\\api.py\", line 61, in request\n    return session.request(method=method, url=url, **kwargs)\n  File \"c:\\users\\oleg3\\pycharmprojects\\homedepot\\venv\\lib\\site-packages\\requests\\sessions.py\", line 530, in request\n    resp = self.send(prep, **send_kwargs)\n  File \"c:\\users\\oleg3\\pycharmprojects\\homedepot\\venv\\lib\\site-packages\\requests\\sessions.py\", line 643, in send\n    r = adapter.send(request, **kwargs)\n  File \"c:\\users\\oleg3\\pycharmprojects\\homedepot\\venv\\lib\\site-packages\\requests\\adapters.py\", line 516, in send\n    raise ConnectionError(e, request=request)\n"}, "start": 1586308592010, "stop": 1586308613439}], "start": 1586308574640, "stop": 1586308630739, "uuid": "bf0e90d7-9d76-499d-bad5-922a223840ae", "historyId": "10c1968ae64c7791a7fce8c5179c385e", "labels": [{"name": "severity", "value": "normal"}, {"name": "feature", "value": "Auto-suggestion"}, {"name": "framework", "value": "behave"}, {"name": "language", "value": "cpython3"}]}